Workbook

Sheet 거래명세서양식
A1: 3권 | C1: 31호 | E1: 거래명세표 | T1: =A1 -> 3권 | V1: =C1 -> 31호 | X1: 거래명세표
A2: 작성일자 | D2: =TODAY() -> 46113 | I2: 공 | J2: 사업자번호 | N2: 560.17.02264 | T2: 작성일자 | W2: =D2 -> 46113 | AB2: 공 | AC2: 사업자번호 | AG2: =N2 -> 560.17.02264
A3: 공급받는자 | D3: 팜에이트 | J3: 상호명 | L3: 이오도 | O3: 성명 | Q3: 유 성덕 | T3: 공급받는자 | W3: =D3 -> 팜에이트 | AC3: 상호명 | AE3: =L3 -> 이오도 | AH3: 성명 | AJ3: =Q3 -> 유 성덕
I4: 급 | J4: 주소 | L4: 부산시 남구 용소로34번길 24-6 | AB4: 급 | AC4: 주소 | AE4: =L4 -> 부산시 남구 용소로34번길 24-6
J5: 업태 | L5: 제조外 | N5: 종목 | P5: 커피外 | AC5: 업태 | AE5: =L5 -> 제조外 | AG5: 종목 | AI5: =P5 -> 커피外
A6: 아래와 같이 계산합니다. | I6: 자 | J6: 전화번호 | M6: 051.621.9771 | T6: 아래와 같이 계산합니다. | AB6: 자 | AC6: 전화번호 | AF6: =M6 -> 051.621.9771
A8: 합계금액 | E8: ="일금"&TEXT(M25+P25,"[DBNum4]")&"원정(\"&TEXT(M25+P25,"#,###")&")" -> 일금이십사만이천원정(\242,000) | T8: 합계금액 | X8: =E8 -> 일금이십사만이천원정(\242,000)
A9: NO | B9: 품목 | F9: 규격/단위 | I9: 수량 | J9: 단가 | M9: 공급가액 | P9: 세액 | T9: NO | U9: 품목 | Y9: 규격/단위 | AB9: 수량 | AC9: 단가 | AF9: 공급가액 | AI9: 세액
A10: 1 | B10: 블렌딩-라이트. | F10: =IF(ISERROR(VLOOKUP(B10,단가!B:C,2,FALSE)),"",VLOOKUP(B10,단가!B:C,2,FALSE)) -> 1/KG | I10: 10 | J10: =IF(ISERROR(VLOOKUP(B10,단가!B:D,3,FALSE)),"",VLOOKUP(B10,단가!B:D,3,FALSE)) -> 22000 | M10: =J10*I10 -> 220000 | P10: =M10/10 -> 22000 | T10: =A10 -> 1 | U10: =B10 -> 블렌딩-라이트. | Y10: =F10 -> 1/KG | AB10: =I10 -> 10 | AC10: =J10 -> 22000 | AF10: =M10 -> 220000 | AI10: =P10 -> 22000
A25: 계 | M25: =SUM(M10:O24) -> 220000 | P25: =SUM(P10:R24) -> 22000 | T25: 계 | AF25: =M25 -> 220000 | AI25: =P25 -> 22000
A26: 입금계좌 | C26: 부산B 101.2087.7763.06 / 이오도 유 성덕 | M26: 인수자 | T26: =A26 -> 입금계좌 | V26: =C26 -> 부산B 101.2087.7763.06 / 이오도 유 성덕 | AF26: 인수자

Sheet 2026년 거래처별-납품현황
A1: 납품일 | B1: 횟수 | C1: 거래처명 | D1: 납품 품목 | E1: 규격/단위 | F1: 수량 | G1: 단가 | H1: 공급가액 | I1: 세액 | J1: 계 | K1: 총액 | M1: =SUBTOTAL(9,J:J) -> #N/A
A2: 01/02 | C2: 주식회사 그랜드타이어 부산시청지점 | D2: 블렌딩-다크(그랜드타이어) | E2: 1/KG | F2: 2 | G2: =VLOOKUP(D2,단가!B:D,3,0) -> 32000 | H2: =F2*G2 -> 64000 | I2: =H2*0.1 -> 6400 | J2: =H2+I2 -> 70400
A3: 01/05 | C3: 주식회사 그랜드타이어 연지점 | D3: 블렌딩-다크(그랜드타이어) | E3: 1/KG | F3: 3 | G3: =VLOOKUP(D3,단가!B:D,3,0) -> 32000 | H3: =F3*G3 -> 96000 | I3: =H3*0.1 -> 9600 | J3: =H3+I3 -> 105600
A4: 01/05 | C4: 라미랑드 | D4: 블렌딩-다크. | E4: 1/KG | F4: 22 | G4: =VLOOKUP(D4,단가!B:D,3,0) -> 25000 | H4: =F4*G4 -> 550000 | I4: =H4*0.1 -> 55000 | J4: =H4+I4 -> 605000
A5: 01/05 | C5: 라미랑드 | D5: 예가체프(25도) | E5: 200/G | F5: 5 | G5: =VLOOKUP(D5,단가!B:D,3,0) -> 10500 | H5: =F5*G5 -> 52500 | I5: =H5*0.1 -> 5250 | J5: =H5+I5 -> 57750
A6: 01/08 | C6: 라미랑드 | D6: 블렌딩-다크. | E6: 1/KG | F6: 5 | G6: =VLOOKUP(D6,단가!B:D,3,0) -> 25000 | H6: =F6*G6 -> 125000 | I6: =H6*0.1 -> 12500 | J6: =H6+I6 -> 137500
A7: 01/08 | C7: 라미랑드 | D7: 케냐(25도) | E7: 200/G | F7: 5 | G7: =VLOOKUP(D7,단가!B:D,3,0) -> 10500 | H7: =F7*G7 -> 52500 | I7: =H7*0.1 -> 5250 | J7: =H7+I7 -> 57750
A8: 01/08 | C8: 라미랑드 | D8: 코케허니(25도) | E8: 200/G | F8: 5 | G8: =VLOOKUP(D8,단가!B:D,3,0) -> 10500 | H8: =F8*G8 -> 52500 | I8: =H8*0.1 -> 5250 | J8: =H8+I8 -> 57750
A9: 01/08 | C9: 라미랑드 | D9: 예가체프(25도) | E9: 200/G | F9: 5 | G9: =VLOOKUP(D9,단가!B:D,3,0) -> 10500 | H9: =F9*G9 -> 52500 | I9: =H9*0.1 -> 5250 | J9: =H9+I9 -> 57750
A10: 01/13 | C10: 라미랑드 | D10: 블렌딩-다크. | E10: 1/KG | F10: 25 | G10: =VLOOKUP(D10,단가!B:D,3,0) -> 25000 | H10: =F10*G10 -> 625000 | I10: =H10*0.1 -> 62500 | J10: =H10+I10 -> 687500
A11: 01/13 | C11: 라미랑드 | D11: 아체가요마운틴(25도) | E11: 200/G | F11: 5 | G11: =VLOOKUP(D11,단가!B:D,3,0) -> 10500 | H11: =F11*G11 -> 52500 | I11: =H11*0.1 -> 5250 | J11: =H11+I11 -> 57750
A12: 01/13 | C12: 라미랑드 | D12: 만델링(25도) | E12: 200/G | F12: 5 | G12: =VLOOKUP(D12,단가!B:D,3,0) -> 10500 | H12: =F12*G12 -> 52500 | I12: =H12*0.1 -> 5250 | J12: =H12+I12 -> 57750
A13: 01/13 | C13: 라미랑드 | D13: 안티구아(25도) | E13: 200/G | F13: 5 | G13: =VLOOKUP(D13,단가!B:D,3,0) -> 10500 | H13: =F13*G13 -> 52500 | I13: =H13*0.1 -> 5250 | J13: =H13+I13 -> 57750
... A20: 01/13 | C20: 라미랑드 | D20: 디카페인(납품). | E20: 200/G | F20: 1 | G20: =VLOOKUP(D20,단가!B:D,3,0) -> 14000 | H20: =F20*G20 -> 14000 | I20: =H20*0.1 -> 1400 | J20: =H20+I20 -> 15400
A21: 01/14 | C21: 메리본 | D21: 블렌딩-다크. | E21: 1/KG | F21: 3 | G21: =VLOOKUP(D21,단가!B:D,3,0) -> 25000 | H21: =F21*G21 -> 75000 | J21: =H21+I21 -> 75000
A22: 01/14 | C22: 길 연산점 | D22: 블렌딩-다크(길) | E22: 1/KG | F22: 10 | G22: =VLOOKUP(D22,단가!B:D,3,0) -> 26000 | H22: =F22*G22 -> 260000 | I22: =H22*0.1 -> 26000 | J22: =H22+I22 -> 286000
A23: 01/14 | C23: 길 연산점 | D23: 디카페인 더치(길) | E23: 1/L | F23: 1 | G23: =VLOOKUP(D23,단가!B:D,3,0) -> 15000 | H23: =F23*G23 -> 15000 | I23: =H23*0.1 -> 1500 | J23: =H23+I23 -> 16500
A24: 01/22 | C24: 길 달맞이점 | D24: 블렌딩-다크(길) | E24: 1/KG | F24: 10 | G24: =VLOOKUP(D24,단가!B:D,3,0) -> 26000 | H24: =F24*G24 -> 260000 | I24: =H24*0.1 -> 26000 | J24: =H24+I24 -> 286000
A25: 01/22 | C25: 길 달맞이점 | D25: 디카페인 더치(길) | E25: 1/L | F25: 2 | G25: =VLOOKUP(D25,단가!B:D,3,0) -> 15000 | H25: =F25*G25 -> 30000 | I25: =H25*0.1 -> 3000 | J25: =H25+I25 -> 33000
A26: 01/22 | C26: 라미랑드 | D26: 블렌딩-다크. | E26: 1/KG | F26: 65 | G26: =VLOOKUP(D26,단가!B:D,3,0) -> 25000 | H26: =F26*G26 -> 1625000 | I26: =H26*0.1 -> 162500 | J26: =H26+I26 -> 1787500
A27: 01/22 | C27: 라미랑드 | D27: 케냐(25도) | E27: 200/G | F27: 5 | G27: =VLOOKUP(D27,단가!B:D,3,0) -> 10500 | H27: =F27*G27 -> 52500 | I27: =H27*0.1 -> 5250 | J27: =H27+I27 -> 57750
A28: 01/22 | C28: 라미랑드 | D28: 코케허니(25도) | E28: 200/G | F28: 5 | G28: =VLOOKUP(D28,단가!B:D,3,0) -> 10500 | H28: =F28*G28 -> 52500 | I28: =H28*0.1 -> 5250 | J28: =H28+I28 -> 57750
A29: 01/22 | C29: 라미랑드 | D29: 예가체프(25도) | E29: 200/G | F29: 5 | G29: =VLOOKUP(D29,단가!B:D,3,0) -> 10500 | H29: =F29*G29 -> 52500 | I29: =H29*0.1 -> 5250 | J29: =H29+I29 -> 57750
A30: 01/22 | C30: 라미랑드 | D30: 모모라(25도) | E30: 200/G | F30: 5 | G30: =VLOOKUP(D30,단가!B:D,3,0) -> 10500 | H30: =F30*G30 -> 52500 | I30: =H30*0.1 -> 5250 | J30: =H30+I30 -> 57750
A31: 01/23 | C31: 메리본 | D31: 블렌딩-다크. | E31: 1/KG | F31: 3 | G31: =VLOOKUP(D31,단가!B:D,3,0) -> 25000 | H31: =F31*G31 -> 75000 | J31: =H31+I31 -> 75000
A32: 01/26 | C32: 라미랑드 | D32: 블렌딩-다크. | E32: 1/KG | F32: 6 | G32: =VLOOKUP(D32,단가!B:D,3,0) -> 25000 | H32: =F32*G32 -> 150000 | I32: =H32*0.1 -> 15000 | J32: =H32+I32 -> 165000
A33: 01/26 | C33: 라미랑드 | D33: 아체가요마운틴(25도) | E33: 200/G | F33: 5 | G33: =VLOOKUP(D33,단가!B:D,3,0) -> 10500 | H33: =F33*G33 -> 52500 | I33: =H33*0.1 -> 5250 | J33: =H33+I33 -> 57750
A34: 01/26 | C34: 라미랑드 | D34: 만델링(25도) | E34: 200/G | F34: 5 | G34: =VLOOKUP(D34,단가!B:D,3,0) -> 10500 | H34: =F34*G34 -> 52500 | I34: =H34*0.1 -> 5250 | J34: =H34+I34 -> 57750
A35: 01/26 | C35: 라미랑드 | D35: 안티구아(25도) | E35: 200/G | F35: 5 | G35: =VLOOKUP(D35,단가!B:D,3,0) -> 10500 | H35: =F35*G35 -> 52500 | I35: =H35*0.1 -> 5250 | J35: =H35+I35 -> 57750
A36: 01/26 | C36: 라미랑드 | D36: 유로(25도) | E36: 200/G | F36: 5 | G36: =VLOOKUP(D36,단가!B:D,3,0) -> 10500 | H36: =F36*G36 -> 52500 | I36: =H36*0.1 -> 5250 | J36: =H36+I36 -> 57750
A37: 01/26 | C37: 라미랑드 | D37: 나리노(25도) | E37: 200/G | F37: 5 | G37: =VLOOKUP(D37,단가!B:D,3,0) -> 10500 | H37: =F37*G37 -> 52500 | I37: =H37*0.1 -> 5250 | J37: =H37+I37 -> 57750
A38: 01/26 | C38: 라미랑드 | D38: 코케허니(25도) | E38: 200/G | F38: 5 | G38: =VLOOKUP(D38,단가!B:D,3,0) -> 10500 | H38: =F38*G38 -> 52500 | I38: =H38*0.1 -> 5250 | J38: =H38+I38 -> 57750
A39: 01/29 | C39: 그랜드타이어 기장지점 | D39: 블렌딩-다크(그랜드타이어) | E39: 1/KG | F39: 2 | G39: =VLOOKUP(D39,단가!B:D,3,0) -> 32000 | H39: =F39*G39 -> 64000 | I39: =H39*0.1 -> 6400 | J39: =H39+I39 -> 70400
A40: 02/02 | C40: 라미랑드 | D40: 케냐(25도) | E40: 200/G | F40: 5 | G40: =VLOOKUP(D40,단가!B:D,3,0) -> 10500 | H40: =F40*G40 -> 52500 | I40: =H40*0.1 -> 5250 | J40: =H40+I40 -> 57750
A41: 02/02 | C41: 라미랑드 | D41: 코케허니(25도) | E41: 200/G | F41: 5 | G41: =VLOOKUP(D41,단가!B:D,3,0) -> 10500 | H41: =F41*G41 -> 52500 | I41: =H41*0.1 -> 5250 | J41: =H41+I41 -> 57750
A42: 02/02 | C42: 라미랑드 | D42: 예가체프(25도) | E42: 200/G | F42: 5 | G42: =VLOOKUP(D42,단가!B:D,3,0) -> 10500 | H42: =F42*G42 -> 52500 | I42: =H42*0.1 -> 5250 | J42: =H42+I42 -> 57750
A43: 02/02 | C43: 라미랑드 | D43: 모모라(25도) | E43: 200/G | F43: 5 | G43: =VLOOKUP(D43,단가!B:D,3,0) -> 10500 | H43: =F43*G43 -> 52500 | I43: =H43*0.1 -> 5250 | J43: =H43+I43 -> 57750
... A53: 02/05 | C53: 라미랑드 | D53: 코케허니(25도) | E53: 200/G | F53: 5 | G53: =VLOOKUP(D53,단가!B:D,3,0) -> 10500 | H53: =F53*G53 -> 52500 | I53: =H53*0.1 -> 5250 | J53: =H53+I53 -> 57750
A54: 02/06 | C54: 메리본 | D54: 블렌딩-다크. | E54: 1/KG | F54: 3 | G54: =VLOOKUP(D54,단가!B:D,3,0) -> 25000 | H54: =F54*G54 -> 75000 | J54: =H54+I54 -> 75000
A55: 02/10 | C55: 라미랑드 | D55: 블렌딩-다크. | E55: 1/KG | F55: 22 | G55: =VLOOKUP(D55,단가!B:D,3,0) -> 25000 | H55: =F55*G55 -> 550000 | I55: =H55*0.1 -> 55000 | J55: =H55+I55 -> 605000
...

Sheet 단가
A1: NO | B1: 품목 | C1: 규격/단위 | D1: 단가 | E1: 공급가액 | F1: 세액 | G1: 합계
A2: 1 | B2: 블렌딩-다크 | C2: 1/KG | D2: 20000 | E2: =D2 -> 20000 | F2: =E2*10% -> 2000 | G2: =SUM(E2:F2) -> 22000
A3: 2 | B3: 블렌딩-다크. | C3: 1/KG | D3: 25000 | E3: =D3 -> 25000 | F3: =E3*10% -> 2500 | G3: =SUM(E3:F3) -> 27500
A4: 3 | B4: 블렌딩-다크(그랜드타이어) | C4: 1/KG | D4: 32000 | E4: =D4 -> 32000 | F4: =E4*10% -> 3200 | G4: =SUM(E4:F4) -> 35200
A5: 4 | B5: 블렌딩-라이트. | C5: 1/KG | D5: 22000 | E5: =D5 -> 22000 | F5: =E5*10% -> 2200 | G5: =SUM(E5:F5) -> 24200
A6: 5 | B6: 블렌딩-라이트 | C6: 1/KG | D6: 20000 | E6: =D6 -> 20000 | F6: =E6*10% -> 2000 | G6: =SUM(E6:F6) -> 22000
A7: 6 | B7: 디카페인. | C7: 200/G | D7: 20000 | E7: =D7 -> 20000 | F7: =E7*10% -> 2000 | G7: =SUM(E7:F7) -> 22000
A8: 7 | B8: 디카페인(납품). | C8: 200/G | D8: 14000 | E8: =D8 -> 14000 | F8: =E8*10% -> 1400 | G8: =SUM(E8:F8) -> 15400
A9: 8 | B9: 디카페인(납품) | C9: 200/G | D9: 10500 | E9: =D9 -> 10500 | F9: =E9*10% -> 1050 | G9: =SUM(E9:F9) -> 11550
A10: 9 | B10: 디카페인(25도) | C10: 200/G | D10: 10500 | E10: =D10 -> 10500 | F10: =E10*10% -> 1050 | G10: =SUM(E10:F10) -> 11550
A11: 10 | B11: 디카페인 | C11: 200/G | D11: 15000 | E11: =D11 -> 15000 | F11: =E11*10% -> 1500 | G11: =SUM(E11:F11) -> 16500
A12: 11 | B12: 블렌딩-길 시그니처 | C12: 1/KG | D12: 19000 | E12: =D12 -> 19000 | F12: =E12*10% -> 1900 | G12: =SUM(E12:F12) -> 20900
A13: 12 | B13: 예가체프(25도) | C13: 200/G | D13: 10500 | E13: =D13 -> 10500 | F13: =E13*10% -> 1050 | G13: =SUM(E13:F13) -> 11550
... A32: 31 | B32: 말라위AAA | C32: 200/G | D32: 15000 | E32: =D32 -> 15000 | F32: =E32*10% -> 1500 | G32: =SUM(E32:F32) -> 16500
A33: 32 | B33: 마타리(25도) | C33: 200/G
A34: 33 | B34: 마타리 | C34: 200/G | E34: =D34 -> 0 | F34: =E34*10% -> 0 | G34: =SUM(E34:F34) -> 0
A35: 34 | B35: 따라주(25도) | C35: 200/G | D35: 10500 | E35: 10500 | F35: 1050 | G35: 11550
A36: 35 | B36: 따라주 | C36: 200/G | D36: 15000 | E36: =D36 -> 15000 | F36: =E36*10% -> 1500 | G36: =SUM(E36:F36) -> 16500
A37: 36 | B37: 아리차(25도) | C37: 200/G | D37: 10500 | E37: =D37 -> 10500 | F37: =E37*10% -> 1050 | G37: =SUM(E37:F37) -> 11550
A38: 37 | B38: 아리차 | C38: 200/G | D38: 15000 | E38: =D38 -> 15000 | F38: =E38*10% -> 1500 | G38: =SUM(E38:F38) -> 16500
A39: 38 | B39: 더치-디카페인(25도) | C39: 500/ML | D39: 10500 | E39: =D39 -> 10500 | F39: =E39*10% -> 1050 | G39: =SUM(E39:F39) -> 11550
A40: 39 | B40: 더치-디카페인 | C40: 500/ML | D40: 15000 | E40: =D40 -> 15000 | F40: =E40*10% -> 1500 | G40: =SUM(E40:F40) -> 16500
A41: 40 | B41: 더치-디카페인(카푸치노) | C41: 500/ML | D41: 10500 | E41: =D41 -> 10500 | F41: =E41*10% -> 1050 | G41: =SUM(E41:F41) -> 11550
A42: 41 | B42: 더치-디카페인. | C42: 500/ML | D42: 20000 | E42: =D42 -> 20000 | F42: =E42*10% -> 2000 | G42: =SUM(E42:F42) -> 22000
A43: 42 | B43: 더치-디카페인(납품). | C43: 500/ML | D43: 14000 | E43: =D43 -> 14000 | F43: =E43*10% -> 1400 | G43: =SUM(E43:F43) -> 15400
A44: 43 | B44: 더치-디카페인(납품) | C44: 500/ML | D44: 10500 | E44: =D44 -> 10500 | F44: =E44*10% -> 1050 | G44: =SUM(E44:F44) -> 11550
A45: 44 | B45: 더치-디카페인(해리단) | C45: 500/ML | D45: 10500 | E45: =D45 -> 10500 | F45: =E45*10% -> 1050 | G45: =SUM(E45:F45) -> 11550
A46: 45 | B46: 더치-다크(25도) | C46: 500/ML | D46: 10500 | E46: =D46 -> 10500 | F46: =E46*10% -> 1050 | G46: =SUM(E46:F46) -> 11550
A47: 46 | B47: 더치-다크 | C47: 500/ML | D47: 15000 | E47: =D47 -> 15000 | F47: =E47*10% -> 1500 | G47: =SUM(E47:F47) -> 16500
... A84: 83 | B84: 더치-길 다크 | C84: 1/L | D84: 6000 | E84: =D84 -> 6000 | F84: =E84*10% -> 600 | G84: =SUM(E84:F84) -> 6600
A85: 84 | B85: 더치-길 디카페인 | C85: 1/L | D85: 8000 | E85: =D85 -> 8000 | F85: =E85*10% -> 800 | G85: =SUM(E85:F85) -> 8800 | H85: 11월 기준: ㈜그랜드타이어, 그랜드타이어 거제지점
A86: 85 | B86: 택배비 | D86: 3000 | E86: =D86 -> 3000 | G86: =SUM(E86:F86) -> 3000
A87: 86 | B87: 케냐(100g) | C87: 100/g | D87: 7500 | E87: =D87 -> 7500 | F87: =E87*10% -> 750 | G87: =SUM(E87:F87) -> 8250
A88: 87 | B88: 유로(100g) | C88: 100/g | D88: 7500 | E88: =D88 -> 7500 | F88: =E88*10% -> 750 | G88: =SUM(E88:F88) -> 8250
A89: 88 | B89: 블랜딩-다크(납품) | C89: 1/KG | D89: 25000 | E89: =D89 -> 25000 | F89: =E89*10% -> 2500 | G89: =SUM(E89:F89) -> 27500
A90: 89 | B90: 블랜딩-다크(샘플) | C90: 1/KG | D90: 0 | E90: =D90 -> 0 | F90: =E90*10% -> 0 | G90: =SUM(E90:F90) -> 0
A91: 90 | B91: 블랜딩-라이트(샘플) | C91: 1/KG | D91: 0 | E91: =D91 -> 0 | F91: =E91*10% -> 0 | G91: =SUM(E91:F91) -> 0
A92: 91 | B92: 머신 렌탈료 | D92: 30000 | E92: =D92 -> 30000 | F92: =E92*10% -> 3000 | G92: =SUM(E92:F92) -> 33000
A93: 92 | B93: 디카페인(납품). | C93: 200/G | D93: 14000 | E93: =D93 -> 14000 | F93: =E93*10% -> 1400 | G93: =SUM(E93:F93) -> 15400
A94: 93 | B94: 디카페인. | C94: 200/G | D94: 20000 | E94: =D94 -> 20000 | F94: =E94*10% -> 2000 | G94: =SUM(E94:F94) -> 22000
...

Sheet 개인주문현황
A1: 납품일 | B1: 횟수 | C1: 거래처명 | D1: 납품 품목 | E1: 규격/단위 | F1: 수량 | G1: 단가 | H1: 공급가액 | I1: 세액 | J1: 계 | K1: 총액
A2: 04/04 | C2: 정영숙 | D2: 코케허니 | E2: 200/G | F2: 1 | G2: =VLOOKUP(D2,단가!B:D,3,0) -> 15000 | H2: =F2*G2 -> 15000 | J2: =H2+I2 -> 15000
A3: 04/04 | C3: 정영숙 | D3: 예가체프 | E3: 200/G | F3: 1 | G3: =VLOOKUP(D3,단가!B:D,3,0) -> 15000 | H3: =F3*G3 -> 15000 | J3: =H3+I3 -> 15000
A4: 04/04 | C4: 박현숙 | D4: 만델링 | E4: 200/G | F4: 1 | G4: =VLOOKUP(D4,단가!B:D,3,0) -> 15000 | H4: =F4*G4 -> 15000 | J4: =H4+I4 -> 15000
A5: 04/04 | C5: 박현숙 | D5: 유로 | E5: 200/G | F5: 1 | G5: =VLOOKUP(D5,단가!B:D,3,0) -> 15000 | H5: =F5*G5 -> 15000 | J5: =H5+I5 -> 15000
A6: 04/07 | C6: 정미혜(어머니) | D6: 예가체프(25도) | E6: 200/G | F6: 15 | G6: =VLOOKUP(D6,단가!B:D,3,0) -> 10500 | H6: =F6*G6 -> 157500 | J6: =H6+I6 -> 157500
A7: 04/07 | C7: 정미혜(어머니) | D7: 케냐(25도) | E7: 200/G | F7: 2 | G7: =VLOOKUP(D7,단가!B:D,3,0) -> 10500 | H7: =F7*G7 -> 21000 | J7: =H7+I7 -> 21000
A8: 04/11 | C8: 류기순 | D8: 블렌딩-다크 | E8: 1/KG | F8: 2 | G8: =VLOOKUP(D8,단가!B:D,3,0) -> 20000 | H8: =F8*G8 -> 40000 | J8: =H8+I8 -> 40000
A9: 04/11 | C9: 이상훈 | D9: 코케허니 | E9: 200/G | F9: 1 | G9: =VLOOKUP(D9,단가!B:D,3,0) -> 15000 | H9: =F9*G9 -> 15000 | J9: =H9+I9 -> 15000
A10: 04/11 | C10: 이상훈 | D10: 케냐(100g) | E10: 100/G | F10: 1 | G10: =VLOOKUP(D10,단가!B:D,3,0) -> 7500 | H10: =F10*G10 -> 7500 | J10: =H10+I10 -> 7500
A11: 04/11 | C11: 이상훈 | D11: 유로(100g) | E11: 100/G | F11: 1 | G11: =VLOOKUP(D11,단가!B:D,3,0) -> 7500 | H11: =F11*G11 -> 7500 | J11: =H11+I11 -> 7500
A12: 04/18 | C12: 이용수 | D12: 코케허니 | E12: 250/G | F12: 2 | G12: 12500 | H12: =F12*G12 -> 25000 | J12: =H12+I12 -> 25000
A13: 04/18 | C13: 이용수 | D13: 모모라 | E13: 250/G | F13: 2 | G13: 12500 | H13: =F13*G13 -> 25000 | J13: =H13+I13 -> 25000
A14: 04/18 | C14: 이용수 | D14: 안티구아 | E14: 250/G | F14: 2 | G14: 10000 | H14: =F14*G14 -> 20000 | J14: =H14+I14 -> 20000
A15: 04/18 | C15: 이용수 | D15: 케냐 | E15: 250/G | F15: 2 | G15: 12500 | H15: =F15*G15 -> 25000 | J15: =H15+I15 -> 25000
A16: 04/22 | C16: 정선영(사촌) | D16: 더치-케냐 | E16: 500/ML | F16: 1 | G16: =VLOOKUP(D16,단가!B:D,3,0) -> 16000 | H16: =F16*G16 -> 16000 | J16: =H16+I16 -> 16000
A17: 04/22 | C17: 정선영(사촌) | D17: 더치-모모라 | E17: 500/ML | F17: 3 | G17: =VLOOKUP(D17,단가!B:D,3,0) -> 16000 | H17: =F17*G17 -> 48000 | J17: =H17+I17 -> 48000
A18: 04/22 | C18: 정선영(사촌) | D18: 더치-예가체프 | E18: 500/ML | F18: 3 | G18: =VLOOKUP(D18,단가!B:D,3,0) -> 15000 | H18: =F18*G18 -> 45000 | J18: =H18+I18 -> 45000
A19: 04/22 | C19: 정선영(사촌) | D19: 더치-나리노 | E19: 500/ML | F19: 1 | G19: =VLOOKUP(D19,단가!B:D,3,0) -> 16000 | H19: =F19*G19 -> 16000 | J19: =H19+I19 -> 16000
A20: 04/23 | C20: 정영숙 | D20: 코케허니 | E20: 200/G | F20: 1 | G20: =VLOOKUP(D20,단가!B:D,3,0) -> 15000 | H20: =F20*G20 -> 15000 | J20: =H20+I20 -> 15000
A21: 04/23 | C21: 정영숙 | D21: 예가체프 | E21: 200/G | F21: 1 | G21: =VLOOKUP(D21,단가!B:D,3,0) -> 15000 | H21: =F21*G21 -> 15000 | J21: =H21+I21 -> 15000
A22: 04/23 | C22: 김혜원 | D22: 더치세트 | E22: 1/SET | F22: 1 | G22: =VLOOKUP(D22,단가!B:D,3,0) -> 30000 | H22: =F22*G22 -> 30000 | J22: =H22+I22 -> 30000
A23: 04/23 | C23: 정미혜(어머니) | D23: 더치미니세트(지인) | E23: 1/SET | F23: 3 | G23: =VLOOKUP(D23,단가!B:D,3,0) -> 29400 | H23: =F23*G23 -> 88200 | J23: =H23+I23 -> 88200
A24: 04/25 | C24: 최이사님 | D24: 블랜딩-다크(샘플) | E24: 1/KG | F24: 1 | G24: =VLOOKUP(D24,단가!B:D,3,0) -> 0 | H24: =F24*G24 -> 0 | J24: =H24+I24 -> 0
A25: 04/25 | C25: 최이사님 | D25: 더치-안티구아 | E25: 500/ML | F25: 1 | G25: =VLOOKUP(D25,단가!B:D,3,0) -> 15000 | H25: =F25*G25 -> 15000 | J25: =H25+I25 -> 15000
A26: 04/25 | C26: 최이사님 | D26: 더치-케냐 | E26: 500/ML | F26: 1 | G26: =VLOOKUP(D26,단가!B:D,3,0) -> 16000 | H26: =F26*G26 -> 16000 | J26: =H26+I26 -> 16000
A27: 04/26 | C27: 이창식 | D27: 더치-나리노 | E27: 500/ML | F27: 1 | G27: =VLOOKUP(D27,단가!B:D,3,0) -> 16000 | H27: =F27*G27 -> 16000 | J27: =H27+I27 -> 16000
... A29: 04/30 | C29: 강정인 | D29: 더치미니세트 | E29: 1/SET | F29: 1 | G29: =VLOOKUP(D29,단가!B:D,3,0) -> 42000 | H29: =F29*G29 -> 42000 | J29: =H29+I29 -> 42000
A30: 04/30 | C30: 정승현 | D30: 블랜딩-다크(샘플) | E30: 1/KG | F30: 2 | G30: =VLOOKUP(D30,단가!B:D,3,0) -> 0 | H30: =F30*G30 -> 0 | I30: =H30*0.1 -> 0 | J30: =H30+I30 -> 0
A31: 04/30 | C31: 정승현 | D31: 블랜딩-라이트(샘플) | E31: 1/KG | F31: 2 | G31: =VLOOKUP(D31,단가!B:D,3,0) -> 0 | H31: =F31*G31 -> 0 | I31: =H31*0.1 -> 0 | J31: =H31+I31 -> 0
A32: 05/06 | C32: 정미혜(어머니) | D32: 더치미니세트(지인) | E32: 1/SET | F32: 4 | G32: =VLOOKUP(D32,단가!B:D,3,0) -> 29400 | H32: =F32*G32 -> 117600 | J32: =H32+I32 -> 117600
A33: 05/09 | C33: 박현숙 | D33: 유로 | E33: 200/G | F33: 1 | G33: =VLOOKUP(D33,단가!B:D,3,0) -> 15000 | H33: =F33*G33 -> 15000 | J33: =H33+I33 -> 15000
A34: 05/09 | C34: 박현숙 | D34: 만델링 | E34: 200/G | F34: 1 | G34: =VLOOKUP(D34,단가!B:D,3,0) -> 15000 | H34: =F34*G34 -> 15000 | J34: =H34+I34 -> 15000
A35: 05/09 | C35: 정영숙 | D35: 코케허니 | E35: 200/G | F35: 1 | G35: =VLOOKUP(D35,단가!B:D,3,0) -> 15000 | H35: =F35*G35 -> 15000 | J35: =H35+I35 -> 15000
A36: 05/09 | C36: 정영숙 | D36: 더치-아체가요마운틴 | E36: 500/ML | F36: 1 | G36: =VLOOKUP(D36,단가!B:D,3,0) -> 15000 | H36: =F36*G36 -> 15000 | J36: =H36+I36 -> 15000
A37: 05/09 | C37: 정영숙 | D37: 더치-코케허니 | E37: 500/ML | F37: 2 | G37: =VLOOKUP(D37,단가!B:D,3,0) -> 16000 | H37: =F37*G37 -> 32000 | J37: =H37+I37 -> 32000
A38: 05/09 | C38: 정영숙 | D38: 예가체프 | E38: 200/G | F38: 1 | G38: =VLOOKUP(D38,단가!B:D,3,0) -> 15000 | H38: =F38*G38 -> 15000 | J38: =H38+I38 -> 15000
A39: 05/09 | C39: 정영숙 | D39: 코케허니 | E39: 200/G | F39: 1 | G39: =VLOOKUP(D39,단가!B:D,3,0) -> 15000 | H39: =F39*G39 -> 15000 | J39: =H39+I39 -> 15000
A40: 05/09 | C40: 박영자 | D40: 더치미니세트 | E40: 1/SET | F40: 4 | G40: =VLOOKUP(D40,단가!B:D,3,0) -> 42000 | H40: =F40*G40 -> 168000 | J40: =H40+I40 -> 168000
A41: 05/09 | C41: 김효정 | D41: 더치세트 | E41: 1/SET | F41: 1 | G41: =VLOOKUP(D41,단가!B:D,3,0) -> 30000 | H41: =F41*G41 -> 30000 | J41: =H41+I41 -> 30000
...

Sheet 거래처별-사업자정보현황
A1: NO | B1: 사업자명 | C1: 사업자번호 | D1: 대표자명 | E1: 업태 | F1: 종목 | G1: 이메일주소 | H1: 담당자명 | I1: 담당자 연락처 | J1: 계산서발행여부
A2: 1 | B2: 민락초등학교 | D2: 황순남 | E2: 교육업 | F2: 초등학교 | J2: Y
A3: 2 | B3: 길 | C3: 472-88-02685 | D3: 유하경 | E3: 프랜차이즈 | F3: 커피 / 브런치 | G3: u_uyoo@naver.com | H3: 유하경 | I3: 010-6450-9663 | J3: Y
A4: 3 | B4: 루카 | C4: 139-35-01309 | D4: 안정환 | E4: 요식업 | F4: 파스타 | G4: wow6954@naver.com | H4: 김성훈 | I4: 010-7436-2068 | J4: Y
A5: 4 | B5: 우리행복요양병원 | E5: 병원 | I5: 010-3650-1381 | J5: N
A6: 5 | B6: 한서병원 응급실 | D6: 최유나 | E6: 병원 | H6: 최유나 | I6: 010-2279-0090 | J6: N
A7: 6 | B7: 25도 커피 부경대점 | J7: Y
A8: 7 | B8: 까페 산성 | C8: 671-27-01550 | D8: 이정숙 | E8: 음식 | F8: 커피 전문점 | H8: 정수임 | J8: Y
A9: 8 | B9: 박현숙 | E9: 개인 | G9: (3만원 이상 택배무료) | J9: N
A10: 9 | B10: 정영숙 | E10: 개인 | G10: (3만원 이상 택배무료) | J10: N
A11: 10 | B11: 노영애 | E11: 개인 | G11: 1kg 이상시 100g당 6000원(방문) | J11: N
A12: 11 | B12: 이용수 | E12: 개인 | G12: 100g 당 4-5000원 (택배) | J12: N
A13: 12 | B13: 김성우 | E13: 개인 | G13: 100g 당 4-5000원 (택배) | J13: N
A14: 13 | B14: 이성훈 | E14: 개인 | G14: (3만원 이상 택배무료) | J14: N
A15: 14 | B15: 정미혜(어머니) | E15: 개인 | G15: 25도 단가랑 같이 | J15: N
A16: 15 | B16: 류기순 | E16: 개인 | J16: N
A17: 16 | B17: 정선영(사촌) | E17: 개인 | J17: N
A18: 17 | B18: 김혜원 | E18: 개인 | J18: N
A19: 18 | B19: 최이사님 | E19: 개인 | J19: N
A20: 19 | B20: 이창식 | E20: 개인 | J20: N
A21: 20 | B21: 강정인 | E21: 개인 | J21: N
A22: 21 | B22: 앤트힐 | C22: 292-73-00409 | D22: 박정윤 | E22: 음식점업 | F22: 서양식 음식점업 | G22: anthilljeju@gmail.com | H22: 박정윤 | I22: 010-6254-6486 | J22: Y
A23: 22 | B23: 시종원 | E23: 개인 | J23: N
A24: 23 | B24: 정숙희 | E24: 개인 | J24: N
A25: 24 | B25: 해리단 빙수 | C25: 351-06-03038 | D25: 조현욱 | E25: 음식 | F25: 한식 | G25: dimtao2019@naver.com | I25: 010-8534-8602 | J25: Y
A26: 25 | B26: 그랜드타이어-거제지점 | C26: 863-85-02634 | D26: 박만식 | E26: 도매 및 소매업 | F26: 자동차 신품 타이어 및 튜브판매업 | G26: khpp4598@naver.com | H26: 김태현 | I26: 010-2318-3769 | J26: Y
A27: 26 | B27: 채선당 | C27: 520-88-02058 | D27: 황원준 | E27: 음식 | F27: 한식 | G27: cutty1917@kakao.com | H27: 황원준 | I27: 010-2316-1917 | J27: Y
A28: 27 | B28: 팜에이트 | C28: 396-85-01265 | D28: 박종위 | E28: 휴게음식점업 | F28: 농산물, 카페, 스마트팜 체험관 | G28: farmtom@farm8.co.kr | H28: 이석우 | I28: 010-9166-2364 | J28: Y
A29: 28 | B29: 카푸치노 | C29: 617-28-97267 | D29: 강치형 | E29: 음식 | F29: 커피전문점 | G29: cappuccinooo@naver.com | H29: 우공숙 | I29: 010-3858-3987 | J29: Y
A30: 29 | B30: 자이언트타이어 북부산점 | C30: 331-39-01354 | D30: 강병규 | E30: 도매 및 소매업 | F30: 타이어 | G30: gullira12@naver.com | H30: 강병규 | J30: Y
A31: 30 | B31: (주)그랜드타이어 | C31: 606-81-75744 | D31: 박만식 | E31: 도, 소매 서비스 | F31: 타이어 / 자동차부분정비 | G31: khppms8428@bill36524.com | H31: 박해준 | I31: 010-2988-1998 | J31: Y
A32: 31 | B32: ㈜ 그레이트타이어 창원지점 | C32: 639-85-01707 | D32: 박만식 | E32: 도매 및 소매업 | F32: 타이어 | G32: khpp1868@naver.com | I32: 010-5452-1615 | J32: Y
A33: 32 | B33: 화담 | C33: 721-74-00563 | D33: 김기호 | E33: 음식점업 | F33: 일반음식점 | G33: style4445@naver.com | H33: 김기호 | I33: 010-9418-6656 | J33: Y
A34: 33 | B34: 주식회사 그랜드타이어 부산시청지점 | C34: 630-85-00832 | D34: 박만식 | E34: 도소매, 서비스 | F34: 타이어, 자동차부분정비 | G34: khpp1054@bill36524.com | I34: 010-5527-5443 | J34: Y
A35: 34 | B35: 주식회사 그랜드타이어 서면지점 | C35: 772-85-00679 | D35: 박만식 | E35: 도소매, 서비스 | F35: 타이어 | G35: khpp18@bill36524.com | J35: Y
A36: 35 | B36: ㈜그랜드타이어 강변지점 | C36: 606-85-27798 | D36: 박만식 | E36: 도소매, 서비스 | F36: 타이어, 자동차부분정비 | G36: khpp1014@naver.com | I36: 010-5414-3513 | J36: Y
A37: 36 | B37: 주식회사 그랜드타이어 연지점 | C37: 323-85-01267 | D37: 박만식 | E37: 도소매 | F37: 타이어 | G37: khpp245@bill36524.com | I37: 010-6667-9876 | J37: Y
A38: 37 | B38: ㈜ 그랜드타이어 정관지점 | C38: 676-85-00328 | D38: 박만식 | E38: 도매업 소매업 | F38: 타이어 | G38: khpp7737@bill36524.com | I38: 010-2318-3769 | J38: Y
A39: 38 | B39: ㈜ 그랜드타이어 양산지점 | C39: 162-85-00299 | D39: 박만식 | E39: 도매업 소매업 | F39: 타이어 | G39: khpp1222@bill36524.com | I39: 010-8462-2388 | J39: Y
A40: 39 | B40: 주식회사 그레이트타이어 서김해지점 | C40: 158-85-02172 | D40: 박만식 | E40: 도소매업 | F40: 타이어 | G40: khpp91@naver.com | I40: 010-8743-8686 | J40: Y
...

Sheet 미수내역
A1: NO | B1: 가맹점명 | C1: 전월미수 | D1: 당월금액 | E1: 입금총액

Sheet 2024년 거래처별-납품현황
A1: 납품일 | B1: 횟수 | C1: 거래처명 | D1: 납품 품목 | E1: 규격/단위 | F1: 수량 | G1: 단가 | H1: 공급가액 | I1: 세액 | J1: 계 | K1: 총액
A2: 03/06 | C2: 길 광안점 | D2: 블렌딩-길 시그니처 | E2: 1/kg | F2: 10 | G2: =VLOOKUP(D2,단가!B:D,3,0) -> 19000 | H2: =F2*G2 -> 190000 | I2: =H2*0.1 -> 19000 | J2: =H2+I2 -> 209000
A3: 03/21 | C3: 길 연산점 | D3: 블렌딩-길 시그니처 | E3: 1/kg | F3: 10 | G3: =VLOOKUP(D3,단가!B:D,3,0) -> 19000 | H3: =F3*G3 -> 190000 | I3: =H3*0.1 -> 19000 | J3: =H3+I3 -> 209000
A4: 03/21 | C4: 길 연산점 | D4: 더치-길 다크 | E4: 1/L | F4: 3 | G4: =VLOOKUP(D4,단가!B:D,3,0) -> 6000 | H4: =F4*G4 -> 18000 | I4: =H4*0.1 -> 1800 | J4: =H4+I4 -> 19800
A5: 03/21 | C5: 길 연산점 | D5: 더치-길 디카페인 | E5: 1/L | F5: 1 | G5: =VLOOKUP(D5,단가!B:D,3,0) -> 8000 | H5: =F5*G5 -> 8000 | I5: =H5*0.1 -> 800 | J5: =H5+I5 -> 8800
A6: 03/23 | C6: 길 대연점 | D6: 블렌딩-길 시그니처 | E6: 1/kg | F6: 10 | G6: =VLOOKUP(D6,단가!B:D,3,0) -> 19000 | H6: =F6*G6 -> 190000 | I6: =H6*0.1 -> 19000 | J6: =H6+I6 -> 209000
A7: 03/23 | C7: 길 대연점 | D7: 더치-길 다크 | E7: 1/L | F7: 3 | G7: =VLOOKUP(D7,단가!B:D,3,0) -> 6000 | H7: =F7*G7 -> 18000 | I7: =H7*0.1 -> 1800 | J7: =H7+I7 -> 19800
A8: 03/23 | C8: 길 대연점 | D8: 더치-길 디카페인 | E8: 1/L | F8: 3 | G8: =VLOOKUP(D8,단가!B:D,3,0) -> 8000 | H8: =F8*G8 -> 24000 | I8: =H8*0.1 -> 2400 | J8: =H8+I8 -> 26400
A9: 03/23 | C9: 길 서면점 | D9: 블렌딩-길 시그니처 | E9: 1/kg | F9: 10 | G9: =VLOOKUP(D9,단가!B:D,3,0) -> 19000 | H9: =F9*G9 -> 190000 | I9: =H9*0.1 -> 19000 | J9: =H9+I9 -> 209000
A10: 03/31 | C10: 루카 | D10: 블렌딩-다크 | E10: 1/kg | F10: 2 | G10: =VLOOKUP(D10,단가!B:D,3,0) -> 20000 | H10: =F10*G10 -> 40000 | I10: =H10*0.1 -> 4000 | J10: =H10+I10 -> 44000
A11: 04/01 | C11: 루카 | D11: 블렌딩-다크 | E11: 1/kg | F11: 1 | G11: =VLOOKUP(D11,단가!B:D,3,0) -> 20000 | H11: =F11*G11 -> 20000 | I11: =H11*0.1 -> 2000 | J11: =H11+I11 -> 22000
A12: 04/03 | C12: 까페 산성 | D12: 블렌딩-다크 | E12: 1/kg | F12: 10 | G12: =VLOOKUP(D12,단가!B:D,3,0) -> 20000 | H12: =F12*G12 -> 200000 | I12: =H12*0.1 -> 20000 | J12: =H12+I12 -> 220000
A13: 04/03 | C13: 까페 산성 | D13: 만델링(25도) | E13: 200/g | F13: 1 | G13: =VLOOKUP(D13,단가!B:D,3,0) -> 10500 | H13: =F13*G13 -> 10500 | I13: =H13*0.1 -> 1050 | J13: =H13+I13 -> 11550
... A56: 04/22 | C56: 길 서면점 | D56: 더치-길 디카페인 | E56: 1/L | F56: 2 | G56: =VLOOKUP(D56,단가!B:D,3,0) -> 8000 | H56: =F56*G56 -> 16000 | I56: =H56*0.1 -> 1600 | J56: =H56+I56 -> 17600
A57: 04/22 | C57: 길 서면점 | D57: 택배비 | F57: 1 | G57: =VLOOKUP(D57,단가!B:D,3,0) -> 3000 | H57: =F57*G57 -> 3000 | J57: =H57+I57 -> 3000
A58: 04/22 | C58: 길 대연점 | D58: 더치-길 디카페인 | E58: 1/L | F58: 2 | G58: =VLOOKUP(D58,단가!B:D,3,0) -> 8000 | H58: =F58*G58 -> 16000 | I58: =H58*0.1 -> 1600 | J58: =H58+I58 -> 17600
A59: 04/22 | C59: 라미랑드 | D59: 유로(25도) | E59: 200/G | F59: 5 | G59: =VLOOKUP(D59,단가!B:D,3,0) -> 10500 | H59: =F59*G59 -> 52500 | I59: =H59*0.1 -> 5250 | J59: =H59+I59 -> 57750
A60: 04/25 | C60: 라미랑드 | D60: 코케허니(25도) | E60: 200/G | F60: 5 | G60: =VLOOKUP(D60,단가!B:D,3,0) -> 10500 | H60: =F60*G60 -> 52500 | I60: =H60*0.1 -> 5250 | J60: =H60+I60 -> 57750
A61: 04/25 | C61: 라미랑드 | D61: 나리노(25도) | E61: 200/G | F61: 5 | G61: =VLOOKUP(D61,단가!B:D,3,0) -> 10500 | H61: =F61*G61 -> 52500 | I61: =H61*0.1 -> 5250 | J61: =H61+I61 -> 57750
A62: 04/25 | C62: 라미랑드 | D62: 예가체프(25도) | E62: 200/G | F62: 5 | G62: =VLOOKUP(D62,단가!B:D,3,0) -> 10500 | H62: =F62*G62 -> 52500 | I62: =H62*0.1 -> 5250 | J62: =H62+I62 -> 57750
A63: 04/25 | C63: 라미랑드 | D63: 아체가요마운틴(25도) | E63: 200/G | F63: 5 | G63: =VLOOKUP(D63,단가!B:D,3,0) -> 10500 | H63: =F63*G63 -> 52500 | I63: =H63*0.1 -> 5250 | J63: =H63+I63 -> 57750
A64: 04/26 | C64: 까페 산성 | D64: 케냐(25도) | E64: 200/G | F64: 1 | G64: =VLOOKUP(D64,단가!B:D,3,0) -> 10500 | H64: =F64*G64 -> 10500 | I64: =H64*0.1 -> 1050 | J64: =H64+I64 -> 11550
A65: 04/26 | C65: 까페 산성 | D65: 아체가요마운틴(25도) | E65: 200/G | F65: 2 | G65: =VLOOKUP(D65,단가!B:D,3,0) -> 10500 | H65: =F65*G65 -> 21000 | I65: =H65*0.1 -> 2100 | J65: =H65+I65 -> 23100
A66: 04/26 | C66: 까페 산성 | D66: 나리노(25도) | E66: 200/G | F66: 1 | G66: =VLOOKUP(D66,단가!B:D,3,0) -> 10500 | H66: =F66*G66 -> 10500 | I66: =H66*0.1 -> 1050 | J66: =H66+I66 -> 11550
A67: 04/27 | C67: 라미랑드 | D67: 안티구아(25도) | E67: 200/G | F67: 5 | G67: =VLOOKUP(D67,단가!B:D,3,0) -> 10500 | H67: =F67*G67 -> 52500 | I67: =H67*0.1 -> 5250 | J67: =H67+I67 -> 57750
A68: 04/27 | C68: 라미랑드 | D68: 모모라(25도) | E68: 200/G | F68: 5 | G68: =VLOOKUP(D68,단가!B:D,3,0) -> 10500 | H68: =F68*G68 -> 52500 | I68: =H68*0.1 -> 5250 | J68: =H68+I68 -> 57750
A69: 04/27 | C69: 라미랑드 | D69: 케냐(25도) | E69: 200/G | F69: 5 | G69: =VLOOKUP(D69,단가!B:D,3,0) -> 10500 | H69: =F69*G69 -> 52500 | I69: =H69*0.1 -> 5250 | J69: =H69+I69 -> 57750
... A291: 08/28 | C291: 길 진도점 | D291: 더치-길 디카페인 | E291: 1/L | F291: 3 | G291: =VLOOKUP(D291,단가!B:D,3,0) -> 8000 | H291: =F291*G291 -> 24000 | I291: =H291*0.1 -> 2400 | J291: =H291+I291 -> 26400
A292: 08/28 | C292: 길 진도점 | D292: 택배비 | F292: 1 | G292: =VLOOKUP(D292,단가!B:D,3,0) -> 3000 | H292: =F292*G292 -> 3000 | J292: =H292+I292 -> 3000
A293: 08/30 | C293: 채선당 | D293: 블렌딩-다크 | E293: 1/KG | F293: 5 | G293: =VLOOKUP(D293,단가!B:D,3,0) -> 20000 | H293: =F293*G293 -> 100000 | I293: =H293*0.1 -> 10000 | J293: =H293+I293 -> 110000
A294: 09/02 | C294: 길 대연점 | D294: 블렌딩-길 시그니처 | E294: 1/KG | F294: 10 | G294: =VLOOKUP(D294,단가!B:D,3,0) -> 19000 | H294: =F294*G294 -> 190000 | I294: =H294*0.1 -> 19000 | J294: =H294+I294 -> 209000
A295: 09/02 | C295: 까페 산성 | D295: 블렌딩-다크 | E295: 1/KG | F295: 15 | G295: =VLOOKUP(D295,단가!B:D,3,0) -> 20000 | H295: =F295*G295 -> 300000 | I295: =H295*0.1 -> 30000 | J295: =H295+I295 -> 330000
A296: 09/03 | C296: 길 광안점 | D296: 블렌딩-길 시그니처 | E296: 1/KG | F296: 10 | G296: =VLOOKUP(D296,단가!B:D,3,0) -> 19000 | H296: =F296*G296 -> 190000 | I296: =H296*0.1 -> 19000 | J296: =H296+I296 -> 209000
A297: 09/03 | C297: 길 광안점 | D297: 더치-길 디카페인 | E297: 1/L | F297: 2 | G297: =VLOOKUP(D297,단가!B:D,3,0) -> 8000 | H297: =F297*G297 -> 16000 | I297: =H297*0.1 -> 1600 | J297: =H297+I297 -> 17600
A298: 09/03 | C298: 길 광안점 | D298: 더치-길 다크 | E298: 1/L | F298: 2 | G298: =VLOOKUP(D298,단가!B:D,3,0) -> 6000 | H298: =F298*G298 -> 12000 | I298: =H298*0.1 -> 1200 | J298: =H298+I298 -> 13200
A299: 09/04 | C299: 라미랑드 | D299: 유로(25도) | E299: 200/G | F299: 5 | G299: =VLOOKUP(D299,단가!B:D,3,0) -> 10500 | H299: =F299*G299 -> 52500 | I299: =H299*0.1 -> 5250 | J299: =H299+I299 -> 57750
A300: 09/04 | C300: 라미랑드 | D300: 안티구아(25도) | E300: 200/G | F300: 5 | G300: =VLOOKUP(D300,단가!B:D,3,0) -> 10500 | H300: =F300*G300 -> 52500 | I300: =H300*0.1 -> 5250 | J300: =H300+I300 -> 57750
A301: 09/04 | C301: 라미랑드 | D301: 아체가요마운틴(25도) | E301: 200/G | F301: 5 | G301: =VLOOKUP(D301,단가!B:D,3,0) -> 10500 | H301: =F301*G301 -> 52500 | I301: =H301*0.1 -> 5250 | J301: =H301+I301 -> 57750
A302: 09/04 | C302: 라미랑드 | D302: 만델링(25도) | E302: 200/G | F302: 5 | G302: =VLOOKUP(D302,단가!B:D,3,0) -> 10500 | H302: =F302*G302 -> 52500 | I302: =H302*0.1 -> 5250 | J302: =H302+I302 -> 57750
A303: 09/04 | C303: 라미랑드 | D303: 케냐(25도) | E303: 200/G | F303: 5 | G303: =VLOOKUP(D303,단가!B:D,3,0) -> 10500 | H303: =F303*G303 -> 52500 | I303: =H303*0.1 -> 5250 | J303: =H303+I303 -> 57750
...

Sheet 2025년 거래처별-납품현황
A1: 납품일 | B1: 횟수 | C1: 거래처명 | D1: 납품 품목 | E1: 규격/단위 | F1: 수량 | G1: 단가 | H1: 공급가액 | I1: 세액 | J1: 계 | K1: 총액 | L1: =SUBTOTAL(9,J:J) -> #N/A
A2: 01/02 | C2: 라미랑드 | D2: 예가체프(25도) | E2: 200/G | F2: 5 | G2: =VLOOKUP(D2,단가!B:D,3,0) -> 10500 | H2: =F2*G2 -> 52500 | I2: =H2*0.1 -> 5250 | J2: =H2+I2 -> 57750
A3: 01/02 | C3: 라미랑드 | D3: 모모라(25도) | E3: 200/G | F3: 5 | G3: =VLOOKUP(D3,단가!B:D,3,0) -> 10500 | H3: =F3*G3 -> 52500 | I3: =H3*0.1 -> 5250 | J3: =H3+I3 -> 57750
A4: 01/02 | C4: 라미랑드 | D4: 코케허니(25도) | E4: 200/G | F4: 5 | G4: =VLOOKUP(D4,단가!B:D,3,0) -> 10500 | H4: =F4*G4 -> 52500 | I4: =H4*0.1 -> 5250 | J4: =H4+I4 -> 57750
A5: 01/02 | C5: 라미랑드 | D5: 케냐(25도) | E5: 200/G | F5: 5 | G5: =VLOOKUP(D5,단가!B:D,3,0) -> 10500 | H5: =F5*G5 -> 52500 | I5: =H5*0.1 -> 5250 | J5: =H5+I5 -> 57750
A6: 01/02 | C6: 라미랑드 | D6: 나리노(25도) | E6: 200/G | F6: 5 | G6: =VLOOKUP(D6,단가!B:D,3,0) -> 10500 | H6: =F6*G6 -> 52500 | I6: =H6*0.1 -> 5250 | J6: =H6+I6 -> 57750
A7: 01/02 | C7: 라미랑드 | D7: 안티구아(25도) | E7: 200/G | F7: 5 | G7: =VLOOKUP(D7,단가!B:D,3,0) -> 10500 | H7: =F7*G7 -> 52500 | I7: =H7*0.1 -> 5250 | J7: =H7+I7 -> 57750
A8: 01/02 | C8: 라미랑드 | D8: 유로(25도) | E8: 200/G | F8: 5 | G8: =VLOOKUP(D8,단가!B:D,3,0) -> 10500 | H8: =F8*G8 -> 52500 | I8: =H8*0.1 -> 5250 | J8: =H8+I8 -> 57750
A9: 01/02 | C9: 라미랑드 | D9: 만델링(25도) | E9: 200/G | F9: 5 | G9: =VLOOKUP(D9,단가!B:D,3,0) -> 10500 | H9: =F9*G9 -> 52500 | I9: =H9*0.1 -> 5250 | J9: =H9+I9 -> 57750
A10: 01/02 | C10: 라미랑드 | D10: 아체가요마운틴(25도) | E10: 200/G | F10: 5 | G10: =VLOOKUP(D10,단가!B:D,3,0) -> 10500 | H10: =F10*G10 -> 52500 | I10: =H10*0.1 -> 5250 | J10: =H10+I10 -> 57750
A11: 01/02 | C11: 라미랑드 | D11: 블렌딩-다크 | E11: 1/KG | F11: 4 | G11: =VLOOKUP(D11,단가!B:D,3,0) -> 20000 | H11: =F11*G11 -> 80000 | I11: =H11*0.1 -> 8000 | J11: =H11+I11 -> 88000
A12: 01/02 | C12: 카푸치노 | D12: 블렌딩-다크 | E12: 1/KG | F12: 3 | G12: =VLOOKUP(D12,단가!B:D,3,0) -> 20000 | H12: =F12*G12 -> 60000 | I12: =H12*0.1 -> 6000 | J12: =H12+I12 -> 66000
A13: 01/07 | C13: 길 달맞이점 | D13: 블렌딩-다크 | E13: 1/KG | F13: 10 | G13: =VLOOKUP(D13,단가!B:D,3,0) -> 20000 | H13: =F13*G13 -> 200000 | I13: =H13*0.1 -> 20000 | J13: =H13+I13 -> 220000
... A54: 01/30 | C54: 라미랑드 | D54: 블렌딩-다크 | E54: 1/KG | F54: 2 | G54: =VLOOKUP(D54,단가!B:D,3,0) -> 20000 | H54: =F54*G54 -> 40000 | I54: =H54*0.1 -> 4000 | J54: =H54+I54 -> 44000
A55: 01/31 | C55: (주)그랜드타이어 | D55: 머신 렌탈료 | F55: 1 | G55: =VLOOKUP(D55,단가!B:D,3,0) -> 30000 | H55: =F55*G55 -> 30000 | I55: =H55*0.1 -> 3000 | J55: =H55+I55 -> 33000
A56: 01/31 | C56: ㈜그랜드타이어 강변지점 | D56: 머신 렌탈료 | F56: 1 | G56: =VLOOKUP(D56,단가!B:D,3,0) -> 30000 | H56: =F56*G56 -> 30000 | I56: =H56*0.1 -> 3000 | J56: =H56+I56 -> 33000
A57: 01/31 | C57: 주식회사 그랜드타이어 서면지점 | D57: 머신 렌탈료 | F57: 1 | G57: =VLOOKUP(D57,단가!B:D,3,0) -> 30000 | H57: =F57*G57 -> 30000 | I57: =H57*0.1 -> 3000 | J57: =H57+I57 -> 33000
A58: 01/31 | C58: 주식회사 그랜드타이어 부산시청지점 | D58: 머신 렌탈료 | F58: 1 | G58: =VLOOKUP(D58,단가!B:D,3,0) -> 30000 | H58: =F58*G58 -> 30000 | I58: =H58*0.1 -> 3000 | J58: =H58+I58 -> 33000
A59: 01/31 | C59: 주식회사 그랜드타이어 연지점 | D59: 머신 렌탈료 | F59: 1 | G59: =VLOOKUP(D59,단가!B:D,3,0) -> 30000 | H59: =F59*G59 -> 30000 | I59: =H59*0.1 -> 3000 | J59: =H59+I59 -> 33000
A60: 01/31 | C60: 그랜드타이어-거제지점 | D60: 머신 렌탈료 | F60: 1 | G60: =VLOOKUP(D60,단가!B:D,3,0) -> 30000 | H60: =F60*G60 -> 30000 | I60: =H60*0.1 -> 3000 | J60: =H60+I60 -> 33000
A61: 01/31 | C61: ㈜ 그레이트타이어 창원지점 | D61: 머신 렌탈료 | F61: 1 | G61: =VLOOKUP(D61,단가!B:D,3,0) -> 30000 | H61: =F61*G61 -> 30000 | I61: =H61*0.1 -> 3000 | J61: =H61+I61 -> 33000
A62: 02/01 | C62: 까페 산성 | D62: 블렌딩-다크 | E62: 1/KG | F62: 5 | G62: =VLOOKUP(D62,단가!B:D,3,0) -> 20000 | H62: =F62*G62 -> 100000 | I62: =H62*0.1 -> 10000 | J62: =H62+I62 -> 110000
A63: 02/01 | C63: 까페 산성 | D63: 디카페인(25도) | E63: 200/G | F63: 1 | G63: =VLOOKUP(D63,단가!B:D,3,0) -> 10500 | H63: =F63*G63 -> 10500 | I63: =H63*0.1 -> 1050 | J63: =H63+I63 -> 11550
A64: 02/01 | C64: 까페 산성 | D64: 더치-디카페인(25도) | E64: 500/ML | F64: 1 | G64: =VLOOKUP(D64,단가!B:D,3,0) -> 10500 | H64: =F64*G64 -> 10500 | I64: =H64*0.1 -> 1050 | J64: =H64+I64 -> 11550
A65: 02/03 | C65: 앤트힐 | D65: 블렌딩-다크 | E65: 1/KG | F65: 5 | G65: =VLOOKUP(D65,단가!B:D,3,0) -> 20000 | H65: =F65*G65 -> 100000 | I65: =H65*0.1 -> 10000 | J65: =H65+I65 -> 110000
A66: 02/03 | C66: 앤트힐 | D66: 블렌딩-라이트. | E66: 1/KG | F66: 5 | G66: =VLOOKUP(D66,단가!B:D,3,0) -> 22000 | H66: =F66*G66 -> 110000 | I66: =H66*0.1 -> 11000 | J66: =H66+I66 -> 121000
A67: 02/03 | C67: 팜에이트 | D67: 블렌딩-라이트. | E67: 1/KG | F67: 10 | G67: =VLOOKUP(D67,단가!B:D,3,0) -> 22000 | H67: =F67*G67 -> 220000 | I67: =H67*0.1 -> 22000 | J67: =H67+I67 -> 242000
A68: 02/03 | C68: 라미랑드 | D68: 블렌딩-다크 | E68: 1/KG | F68: 5 | G68: =VLOOKUP(D68,단가!B:D,3,0) -> 20000 | H68: =F68*G68 -> 100000 | I68: =H68*0.1 -> 10000 | J68: =H68+I68 -> 110000
A69: 02/03 | C69: 라미랑드 | D69: 예가체프(25도) | E69: 200/G | F69: 2 | G69: =VLOOKUP(D69,단가!B:D,3,0) -> 10500 | H69: =F69*G69 -> 21000 | I69: =H69*0.1 -> 2100 | J69: =H69+I69 -> 23100
A70: 02/05 | C70: 길 달맞이점 | D70: 더치-길 디카페인 | E70: 1/L | F70: 2 | G70: =VLOOKUP(D70,단가!B:D,3,0) -> 8000 | H70: =F70*G70 -> 16000 | I70: =H70*0.1 -> 1600 | J70: =H70+I70 -> 17600
A71: 02/05 | C71: 길 달맞이점 | D71: 택배비 | F71: 1 | G71: =VLOOKUP(D71,단가!B:D,3,0) -> 3000 | H71: =F71*G71 -> 3000 | I71: 300 | J71: =H71+I71 -> 3300
A72: 02/06 | C72: (주)그랜드타이어 | D72: 블렌딩-다크(그랜드타이어) | E72: 1/KG | F72: 4 | G72: =VLOOKUP(D72,단가!B:D,3,0) -> 32000 | H72: =F72*G72 -> 128000 | I72: =H72*0.1 -> 12800 | J72: =H72+I72 -> 140800
A73: 02/06 | C73: 라미랑드 | D73: 유로(25도) | E73: 200/G | F73: 5 | G73: =VLOOKUP(D73,단가!B:D,3,0) -> 10500 | H73: =F73*G73 -> 52500 | I73: =H73*0.1 -> 5250 | J73: =H73+I73 -> 57750
A74: 02/06 | C74: 라미랑드 | D74: 예가체프(25도) | E74: 200/G | F74: 5 | G74: =VLOOKUP(D74,단가!B:D,3,0) -> 10500 | H74: =F74*G74 -> 52500 | I74: =H74*0.1 -> 5250 | J74: =H74+I74 -> 57750
A75: 02/06 | C75: 라미랑드 | D75: 안티구아(25도) | E75: 200/G | F75: 5 | G75: =VLOOKUP(D75,단가!B:D,3,0) -> 10500 | H75: =F75*G75 -> 52500 | I75: =H75*0.1 -> 5250 | J75: =H75+I75 -> 57750
A76: 02/06 | C76: 라미랑드 | D76: 모모라(25도) | E76: 200/G | F76: 5 | G76: =VLOOKUP(D76,단가!B:D,3,0) -> 10500 | H76: =F76*G76 -> 52500 | I76: =H76*0.1 -> 5250 | J76: =H76+I76 -> 57750
A77: 02/06 | C77: 라미랑드 | D77: 코케허니(25도) | E77: 200/G | F77: 5 | G77: =VLOOKUP(D77,단가!B:D,3,0) -> 10500 | H77: =F77*G77 -> 52500 | I77: =H77*0.1 -> 5250 | J77: =H77+I77 -> 57750
A78: 02/06 | C78: 라미랑드 | D78: 나리노(25도) | E78: 200/G | F78: 5 | G78: =VLOOKUP(D78,단가!B:D,3,0) -> 10500 | H78: =F78*G78 -> 52500 | I78: =H78*0.1 -> 5250 | J78: =H78+I78 -> 57750
A79: 02/06 | C79: 라미랑드 | D79: 케냐(25도) | E79: 200/G | F79: 5 | G79: =VLOOKUP(D79,단가!B:D,3,0) -> 10500 | H79: =F79*G79 -> 52500 | I79: =H79*0.1 -> 5250 | J79: =H79+I79 -> 57750
A80: 02/06 | C80: 라미랑드 | D80: 아체가요마운틴(25도) | E80: 200/G | F80: 5 | G80: =VLOOKUP(D80,단가!B:D,3,0) -> 10500 | H80: =F80*G80 -> 52500 | I80: =H80*0.1 -> 5250 | J80: =H80+I80 -> 57750
...
